> [!NOTE]
> Вы можете прочитать эту статью на сайте: https://diveintopython.org/ru/learn/exceptions

Одним из фундаментальных аспектов Python, который способствует его надежности, является система обработки исключений. Исключения в Python - это ошибки, обнаруженные во время выполнения, которые могут нарушить нормальный поток программы. Понимание исключений критически важно для написания надежного и эффективного кода на Python.

Исключение в Python может возникнуть в различных ситуациях, например при делении на ноль, доступе к несуществующему файлу или попытке импортировать несуществующий модуль. Вместо того, чтобы позволить этим ошибкам завершить программу, Python позволяет программисту перехватывать и обрабатывать эти исключения. Это делается через блок try-except, где программист пытается выполнить код, который может вызвать исключение в блоке try, и обрабатывает исключение в блоке except.

Система исключений Python иерархическая, все исключения наследуются от класса BaseException. Эта система включает в себя встроенные исключения, такие как `IOError`, `ValueError`, `ZeroDivisionError` и многие другие. Программисты также могут определять свои собственные пользовательские исключения для обработки конкретных условий ошибок, уникальных для их приложений.

## Для чего необходимы Exceptions?

В программировании на Python исключения являются важной частью написания чистого, надежного и эффективного кода. Исключения используются для  обработки ошибок и управления потоком программы, когда возникают неожиданные проблемы. Используя структуру `try except`, программисты могут предвидеть потенциальные проблемы и обеспечить, чтобы их код мог справиться с необычными обстоятельствами без сбоев. Механизм исключений Python повышает надежность кода и пользовательский опыт за счет обработки ошибок и предоставления информативной обратной связи.

### Понимание Try Except в Python

Базовая структура обработки исключений в Python включает в себя блоки `try` и `except`. Вот как это работает:

1. **Блок Try:** Этот блок содержит код, который может генерировать исключение или ошибку. Python попытается выполнить этот код, и если произойдет ошибка, он остановит выполнение этого блока и перейдет к блоку `except`.
   
2. **Блок Except:** Код в этом блоке будет выполнен, если в блоке try произойдет ошибка. Это позволяет обрабатывать ошибки, вести журнал или предпринимать действия по восстановлению.

### Пример: Базовый Try Except

```python
try:
    result = 10 / 0
except ZeroDivisionError:
    print("Cannot divide by zero!")
```

### Обработка Нескольких Исключений

Python позволяет обрабатывать несколько исключений, чтобы различать разные типы ошибок. Эта возможность критически важна для создания более детализированной логики обработки ошибок и предоставления специфических ответов для различных условий ошибок.

### Пример: Несколько Try Except

```python
try:
    with open('non_existent_file.txt', 'r') as file:
        print(file.read())
except FileNotFoundError:
    print("The file does not exist.")
except Exception as e:
    print(f"An error occurred: {str(e)}")
```

### Рекомендации по Использованию Exceptions

Правильное использование исключений является ключом к максимизации их преимуществ в вашем коде на Python. Вот несколько лучших практик, которым следует следовать:

- **Используйте специфические классы исключений** по возможности, вместо того чтобы перехватывать все исключения. Эта практика повышает ясность и надежность обработки ошибок.
- **Избегайте пустого except:** Всегда уточняйте тип исключения, которое нужно перехватить, чтобы предотвратить перехват неожиданных исключений.
- **Используйте finally для очистки:** Блок `finally` может быть использован для гарантии выполнения определенных действий, таких как закрытие файла, независимо от того, произошло ли исключение.

> Примечание: При использовании исключений важно найти баланс между обработкой реальных ошибок и управлением потоком программы. Чрезмерное использование исключений для управления потоком может привести к коду, который сложно понять и поддерживать.

### Когда Использовать Исключения

В программировании на Python исключения следует использовать в ситуациях, когда ошибка ожидаема и может быть обработана таким образом, что программа может продолжить работу или корректно завершиться. Это включает, но не ограничивается:

1. Операции ввода/вывода
2. Работа с файлами или сетевыми соединениями
3. Разбор данных
4. Работа с внешними API или библиотеками, которые могут выдавать сбои в определенных условиях

Эффективное использование исключений позволяет разработчикам на Python создавать устойчивые приложения, способные пережить ошибки и обеспечить плавный пользовательский опыт.

## Типы Исключений

При работе с Python эффективная обработка ошибок имеет решающее значение для создания надежных приложений. Python предоставляет иерархию типов исключений, позволяя разработчикам перехватывать и реагировать на различные ошибки в их коде. Понимание этих типов и как `print` информацию об исключении может значительно помочь в отладке и обработке ошибок.

### Распространенные Типы Исключений

Исключения в Python охватывают широкий диапазон типов ошибок, от ошибок синтаксиса до ошибок выполнения. Вот взгляд на некоторые часто встречающиеся типы исключений:

- `SyntaxError`: Возникает, когда Python не может понять ваш код.
- `NameError`: Происходит, когда локальное или глобальное имя не найдено.
- `TypeError`: Вызвано операцией или функцией, примененной к объекту неподходящего типа.
- `ValueError`: Возникает, когда функция получает аргумент с правильным типом, но неподходящим значением.
- `IndexError`: Срабатывает при попытке доступа к индексу, который выходит за диапазон.

### Как Вывести Тип Exceptions

Когда происходит исключение, может быть полезно знать, с каким именно типом исключения вы имеете дело. Вы можете перехватить и `print` тип исключения, используя операторы `try` и `except` с `except Exception as e`.

### Пример: Печать Исключения

```python
try:
    # This will raise a ValueError
    print(int("xyz"))
except Exception as e:
    print(f"Caught an exception: {type(e).__name__}")
```

Этот пример выведет:

```python
Caught an exception: ValueError
```

### Пример: Печать Конкретных Исключений

Вы также можете отлавливать и обрабатывать несколько конкретных исключений отдельно:

```python
try:
    # Code that can raise multiple exceptions
    result = 10 / 0
except ZeroDivisionError as e:
    print(f"Caught a division error: {type(e).__name__}")
except ValueError as e:
    print(f"Caught a value error: {type(e).__name__}")
```

Этот код конкретно сообщит вам, было ли перехвачено исключение `ZeroDivisionError` или `ValueError`.

### Использование Таблицы Иерархии Исключений

Иерархия исключений Python позволяет перехватывать исключения на основе их специфичности. Вот упрощенный вид иерархии исключений:

| Базовое Исключение | Наследуется От | Описание |
| --------------- | ------------- | ----------- |
| `BaseException` | N/A | Базовый класс для всех встроенных исключений |
| `Exception` | `BaseException` | Все встроенные исключения, не приводящие к завершению системы |
| `ArithmeticError` | `Exception` | Базовый класс для ошибок арифметики |
| `BufferError` | `Exception` | Вызывается, когда операция, связанная с буфером, не может быть выполнена |
| `LookupError` | `Exception` | Базовый класс для ошибок поиска |

> Примечание: Эта таблица не охватывает все возможные исключения, но дает представление о структуре наследования, которое может быть полезным для эффективного перехвата исключений.

## Обработка Исключений

Обработка исключений в Python - это критически важный аспект написания надежного и поддерживаемого кода. Исключение в Python - это событие, которое нарушает нормальный поток программы. Python предоставляет встроенные исключения и позволяет пользователям определять свои собственные. Знание того, как правильно перехватывать и обрабатывать эти исключения, имеет решающее значение для отладки и предотвращения ошибок в ваших приложениях.

### Встроенные Исключения Python

Встроенные исключения Python охватывают широкий спектр условий ошибок. От `ValueError`, который указывает на неподходящее значение, до `FileNotFoundError`, который сигнализирует о том, что файл не может быть найден, эти исключения помогают разработчикам быстро диагностировать проблемы.

### Перехват Исключений С Помощью `try` и `except`

Базовая структура для обработки исключений в Python включает в себя блоки `try` и `except`. Вы помещаете код, который может вызвать исключение, внутри блока `try`, а код для выполнения, если происходит исключение, в блоке `except`.

### Пример: Базовый Блок `try` и `except`

```python
try:
    # Code that might raise an exception
    result = 10 / 0
except ZeroDivisionError:
    print("Caught a division by zero!")
```

В приведенном выше коде, попытка деления на ноль вызывает `ZeroDivisionError`, который затем перехватывается блоком `except`, предотвращая аварийное завершение программы.

### Перехват Любого Исключения

Чтобы перехватить любое исключение, можно использовать простую конструкцию `except:`, которая перехватит все исключения. Однако, перехват всех исключений обычно не рекомендуется, так как это может усложнить отладку.

### Пример: Перехват Любого Исключения

```python
try:
    # Code that might raise any exception
    result = 10 / unknown_var
except:
    print("An unexpected error occurred!")
```

### Обработка Конкретных Исключений

Для более тонкого контроля над тем, какие исключения перехватывать, Python позволяет указывать несколько блоков `except`, каждый из которых обрабатывает разные типы исключений.

### Except с `SystemExit`

Особая осторожность необходима при работе с `SystemExit`, так как перехват этого исключения может мешать нормальному процессу завершения работы скрипта. `SystemExit` вызывается функцией `sys.exit()` и в общем случае должен быть разрешен к распространению.

> Примечание: Используйте `except SystemExit`, чтобы явно перехватить исключение `SystemExit`, если вам необходима конкретная операция очистки перед выходом из скрипта.

### Логирование Исключений

Логирование исключений может предоставить массу информации для отладки. Модуль [logging](https://docs.python.org/3/library/logging.html) Python может быть использован для логирования исключений, предоставляя не только сообщение об ошибке, но и трассировку.

### Пример: Пример Логирования Исключения

```python
import logging

try:
    # Code that might raise an exception
    result = 1 / 0
except ZeroDivisionError:
    logging.exception("Exception occurred")
```

Это будет записывать сообщение исключения вместе с трассировкой, помогая в отладке.

### Лучшие Практики Обработки Исключений

1. **Перехватывайте конкретные исключения**, когда это возможно.
2. **Используйте `finally`** для действий по очистке, которые должны быть выполнены в любом случае.
3. **Избегайте перехвата `SystemExit`**, если у вас нет на то веских причин.
4. **Записывайте исключения** для помощи в отладке.
5. **Используйте пользовательские исключения** для более ясной отчетности об ошибках.

Следование этим рекомендациям улучшит надежность и ясность вашего Python кода при работе с исключениями.

## Генерация Исключений

При разработке приложений на Python, грациозная обработка ошибок критически важна для обеспечения надежности и устойчивости вашего программного обеспечения. Генерируя исключения, вы можете контролировать поток вашей программы, когда возникают неожиданные ситуации. Эта статья охватывает основы вызова исключений в Python, предоставляя понимание о том, как эффективно вызвать исключение или бросить исключение в вашем коде.

### Понимание Обработки Исключений

Обработка исключений - это фундаментальное понятие в Python, которое позволяет разработчику предвидеть и управлять ошибками во время выполнения программы. Когда говорят о вызове исключения в Python, это часто относится к намеренному созданию исключений, когда выполняются определенные условия.

### Как `raise` Исключение

Вызов исключения в Python прост. Вы можете использовать ключевое слово `raise`, за которым следует экземпляр исключения, которое вы хотите бросить. Это обычно называется вызовом исключения.

### Пример: Вызов `ValueError`

```python
def check_age(age):
    if age < 18:
        raise ValueError("Access denied due to age restrictions.")
    return "Access granted."

try:
    user_status = check_age(17)
    print(user_status)
except ValueError as err:
    print(err)
```

> Примечание: В этом примере, попытка вызвать `check_age` с аргументом меньше 18 приводит к `ValueError`, который затем перехватывается в блоке `except`.

### Генерация Собственного Исключения

Вы также можете определять свои собственные классы исключений, наследуя от встроенного в Python класса `Exception`. Это полезно, когда необходимо сгенерировать исключение, которое более специфично для контекста вашего приложения.

```python
class AgeRestrictionError(Exception):
    """Exception raised for errors in age restrictions."""

    def __init__(self, message="Age is below the required limit."):
        self.message = message
        super().__init__(self.message)

def verify_age(age):
    if age < 18:
        raise AgeRestrictionError
    return "Verification successful."

try:
    result = verify_age(16)
    print(result)
except AgeRestrictionError as err:
    print(err)
```

> Примечание: Пользовательские исключения позволяют создавать более описательные ошибки, делая ваш код проще для понимания и отладки.

### Когда Использовать Обработку Исключений

Вот обстоятельства, при которых вы можете захотеть `raise` исключение:

1. **Проверка ввода:** Убедитесь, что данные, вводимые в функцию, действительны.
2. **Доступность ресурсов:** Проверьте, доступны ли необходимые ресурсы (например, файлы или сеть).
3. **Результаты операции:** Проверьте итог операции, чтобы убедиться, что он соответствует определенным критериям.

Использование исключений, где это уместно, обеспечивает не только надежность вашего кода, но и его легкость в обслуживании и понимании.

| Ситуация           | Причина для возбуждения исключения                                                        |
| ------------------ | -------------------------------------------------------------------------------------------|
| Неверные параметры | Чтобы предотвратить продолжение работы функций со значениями, которые могут привести к неожиданным результатам      |
| Сбой операции      | Чтобы остановить поток выполнения, когда операцию нельзя завершить как предполагалось               |
| Управление ресурсами | Чтобы убедиться, что ресурсы, такие как файлы или сетевые соединения, действительно доступны и их можно использовать |

Понимание и применение стратегий возбуждения исключений являются жизненно важными навыками в программировании на Python. Они не только помогают сделать ваш код более надежным, но и сигнализируют другим разработчикам о возможных подводных камнях. Помните, что эффективная обработка исключений может значительно улучшить отладку и устойчивость вашего приложения.

## Использование Конструкции `try/except/else`

При работе с Python обработка исключений становится неотъемлемой частью написания надежного и безошибочного кода. Конструкция `try/except/else` - мощная функция, которая позволяет разработчикам предвидеть потенциальные ошибки, изящно их обрабатывать, а также выполнять код, который должен выполняться только если исключения не были вызваны. Это руководство продемонстрирует, как эффективно использовать эту конструкцию на примерах, сосредотачиваясь на том, как `print` и выбрасывать исключения в Python.

### Понимание `try/Except/else`

Блок `try` позволяет проверить блок кода на наличие ошибок. Блок `except` позволяет вам обработать ошибку. Блок `else` выполняет часть кода, когда исключений нет. Умение профессионально использовать эти конструкции может значительно улучшить надежность и читаемость вашего кода.

### Пример: Основной Синтаксис `try/except/else`

```python
try:
  pass
   # Attempt to execute this code
except ExceptionType:
  pass
   # Handle the exception
else:
  pass
   # Execute code if no exceptions
```

## Примеры Использования `try/except/else`

Давайте погрузимся в практические примеры, чтобы понять, как применять эти конструкции в повседневных задачах программирования.

### Пример: Обработка Ошибки `ZeroDivisionError`

Здесь мы будем обрабатывать ошибку деления на ноль, которая является обычной ловушкой для начинающих.

```python
try:
    result = 10 / 0
except ZeroDivisionError:
    print("ZeroDivisionError: Cannot divide by zero.")
else:
    print(f"Division result is {result}")
```

В этом примере блок `except` перехватывает `ZeroDivisionError`, тем самым предотвращая падение программы, и использует `print exception python` для информирования пользователя об ошибке.

### Пример: Чтение Файла с Обработкой Исключений

Чтение файлов, не зная, существуют ли они, может привести к `IOError`. Вот как обрабатывать подобные ситуации.

```python
try:
    with open('nonexistent_file.txt', 'r') as file:
        print(file.read())
except IOError:
    print("IOError: File not found.")
else:
    print("File read successfully.")
```

Этот фрагмент кода информирует пользователя, когда файл не существует, вместо того, чтобы внезапно завершать программу.

## Печать и Создание Исключений

### Как `print` Исключение

Печать конкретной проблемы может помочь в отладке. Вы можете перехватить и `print` исключение следующим образом:

```python
try:
    # some code that can raise an exception
except Exception as e:
    print(f"An error occurred: {e}")
```

### Лучшие Практики Использования `try/except/else`

Вот краткое изложение лучших практик при использовании конструкции try/except/else в Python:

1. **Перехватывайте конкретные исключения**: Всегда старайтесь перехватывать конкретные исключения, а не использовать широкую инструкцию `except`. Такой подход предотвращает перехват непреднамеренных исключений.

2. **Используйте Else для кода, зависимого от блока Try**: Блок else должен содержать код, который должен выполняться только если блок try не вызвал исключение.

3. **Держите блок try минимальным**: Включайте в блок try только код, который может вызвать исключение, чтобы избежать перехвата исключений, которые не должны обрабатываться блоком except.

Следуя этим практикам, разработчики могут обеспечить эффективность и легкость устранения неполадок своего кода на Python.

## Использование Конструкции `try/finally`

При написании кода важно убедиться, что определенные операции выполняются в любом случае. Это особенно важно при работе с внешними ресурсами или действиями, которые должны быть завершены, например, при закрытии файла или сетевого соединения. Python предоставляет мощную конструкцию для решения этой задачи: механизм `try/finally`, неотъемлемая часть обработки исключений, который обеспечивает выполнение кода очистки или завершения.

### Что Такое Конструкция `try/finally`

В Python конструкция `try/finally` используется для определения блока кода, где часть `try` позволяет проверить блок кода на наличие ошибок, а часть `finally` позволяет выполнить код, независимо от результата блока try. Эта структура обеспечивает выполнение блока finally даже если в блоке try произошла ошибка.

Эта конструкция особенно важна для управления ресурсами, такими как работа с файлами или сетевыми соединениями, где вы должны убедиться, что ресурсы правильно освобождены после их использования, независимо от того, произошла ли ошибка или нет.

### Как Использовать `try/finally`

Вот пошаговое руководство:

1. Начните с ключевого слова `try`, за которым следует двоеточие, чтобы начать блок try.
2. Напишите код, который вы хотите выполнить и который может вызвать ошибку, внутри блока try.
3. После блока try используйте ключевое слово `finally`, за которым следует двоеточие, чтобы начать блок finally.
4. Напишите код, который должен быть выполнен независимо от того, произошла ли ошибка в блоке try.

> Примечание: Конструкция `try/finally` может использоваться с блоком `except` или без него. Однако этот раздел сосредоточен на использовании без явной обработки исключений (`except`).

### Примеры Кода Для `try/finally`

Чтобы проиллюстрировать конструкцию `try/finally`, давайте рассмотрим два примера.

Представьте, что вы работаете с файлом и хотите убедиться, что он правильно закрыт после ваших операций:

```python
try:
    f = open("test.txt", "r")
    print(f.read())
finally:
    f.close()
    print("File has been closed.")
```

В этом примере, независимо от того, что происходит после открытия файла, блок `finally` гарантирует, что файл будет закрыт.

Вот пример, связанный с более общим сценарием управления ресурсами:

```python
resource_allocated = False
try:
    print("Allocating Resource")
    resource_allocated = True
    # Simulate an error
    raise Exception("An error occurred!")
finally:
    if resource_allocated:
        print("Cleaning up Resource")
```

Даже если ошибка происходит и генерируется после выделения ресурса, блок `finally` выполняется, обеспечивая очистку ресурса.

### Лучшие Практики Использования `try/finally` в Python

- **Управление ресурсами**: Всегда используйте `try/finally` при работе с управлением ресурсами, такими как работа с файлами, сетевое взаимодействие или работа с базами данных, чтобы убедиться, что ресурсы правильно освобождаются.
- **Избегайте сложной логики в Finally**: Держите логику блока finally простой и понятной. Его основная цель - очистка и освобождение ресурсов.
- **Отладка и регистрация ошибок**: Хотя конструкция `try/finally` не обрабатывает исключения, убедитесь, что любые потенциальные ошибки занесены в журнал или управляются вне этой конструкции для лучшей отладки и отслеживания ошибок.

## Объединение `finally` и `except` через Вложение

При работе с обработкой исключений в Python важно понимать, как эффективно управлять и ошибками, и процессом очистки. Объединение блоков `finally` и `except` через вложение предоставляет изощренный способ обработки исключений (`except Exception as e`) и обеспечения выполнения необходимых операций очистки независимо от того, произошла ли ошибка. Этот подход особенно полезен в сценариях, когда вам нужен высокий уровень контроля над обработкой ошибок и управлением ресурсами.

### Понимание Вложенного Try Except в Python

Вложение инструкций `try` в Python позволяет более тонко подходить к обработке исключений. Размещая блок `try-except` внутри другого блока `try`, вы можете перехватывать исключения более детально. Эта техника, известная как **python nested try except**, полезна при работе с кодом, который может вызывать несколько типов исключений.

### Основные Вложенные `try` `except`

```python
try:
    # Outer try block
    try:
        # Possible error-prone code
        result = 10 / 0
    except ZeroDivisionError as e:
        print(f"Caught an exception: {e}")
    finally:
        print("This is the inner finally block executing.")
except Exception as e:
    # Outer except block
    print(f"Outer exception caught: {e}")
finally:
    print("This is the outer finally block executing.")
```

В этом примере мы обрабатываем `ZeroDivisionError` внутри внутреннего блока `try-except`, демонстрируя метод **универсальной обработки исключений**. Оба блока `finally` гарантируют, что код очистки будет выполнен, показывая, как эффективно объединить блоки `finally` и `except`.

### Продвинутый Сценарий

```python
try:
    # Outer block attempting file operations
    with open("nonexistent_file.txt", "r") as f:
        content = f.read()
    try:
        # Code that could potentially cause another exception
        process_content(content)
    except Exception as e:
        print(f"Error processing content: {e}")
    finally:
        print("Inner clean-up code executed.")
except FileNotFoundError as e:
    print(f"File error: {e}")
finally:
    print("Outer clean-up code executed, ensuring resources are freed.")
```

Этот продвинутый пример иллюстрирует обработку конкретного `FileNotFoundError` и общего исключения с использованием подхода **except exception as e**. Вложенные блоки `try-except` позволяют точно контролировать обработку исключений и управление ресурсами.

> Примечание: Всегда убедитесь, что блок `finally` содержит код, который должен быть выполнен, например, закрытие файлов или освобождение системных ресурсов, чтобы предотвратить утечку ресурсов.

### Преимущества Вложенности Finally и Except

1. **Улучшенная обработка ошибок**: Позволяет обрабатывать различные исключения на нескольких уровнях, обеспечивая гибкость.
2. **Управление ресурсами**: Гарантирует выполнение кода очистки, что критически важно для управления ресурсами, такими как обработчики файлов или сетевые соединения.
3. **Читаемость кода**: Упрощает понимание, какая часть кода ответственна за обработку конкретных исключений.

Использование вложенных блоков `try-except` в сочетании с `finally` является мощным паттерном в **обработке исключений**. Он предоставляет необходимый инструментарий для написания надежного и толерантного к ошибкам кода, обеспечивая как точную обработку ошибок, так и эффективное управление ресурсами. Этот подход особенно полезен в сложных приложениях, где неспособность освободить ресурсы или корректно обработать ошибки может иметь серьезные последствия.

## Объекты Исключений

При работе с Python встреча с ошибками и исключениями неизбежна. Исключения - это объекты в Python, которые нарушают нормальное течение выполнения программы, когда происходит ошибка. Python предоставляет иерархию встроенных классов исключений, которые могут быть расширены для создания пользовательских исключений. Этот механизм имеет решающее значение для обработки ошибок и способствует надежности приложений на Python.

### Что Такое Исключения

Исключения - это объекты, которые инкапсулируют информацию об ошибках, возникающих во время выполнения программы. Когда происходит ошибка, Python генерирует объект исключения. Если он не обработан, этот объект распространяется вверх и может привести к завершению программы. Корректная обработка исключений позволяет вашей программе изящно реагировать на ошибки.

### Класс Исключений Python

Базовым классом для всех исключений в Python является `Exception`. Этот класс может быть подклассифицирован для создания пользовательских исключений, что позволяет разработчикам добавлять дополнительную функциональность или информацию к своим процедурам обработки исключений.

### Создание Пользовательского Исключения

Чтобы создать пользовательское исключение, вы просто подклассифицируете класс `Exception` и определите любые дополнительные методы или свойства, которые вам нужны.

```python
class MyCustomError(Exception):
    """A custom exception class."""
    pass
```

### Добавление Сообщения об Исключении

При вызове пользовательского исключения часто полезно предоставить подробное сообщение об ошибке, передав строку в конструктор исключения. Это сообщение сохраняется в атрибуте `args` объекта исключения.

```python
raise MyCustomError("This is an error message")
```

### Работа с Объектами Исключений

Когда возникает исключение, его можно перехватить, используя блок `try` и `except`. Затем объект исключения может быть доступен в блоке `except` для получения информации об ошибке.

1. Перехват исключений
2. Доступ к сообщению исключения
3. Пользовательская обработка в зависимости от типа исключения

### Доступ к Сообщению Исключения

В этом примере мы получаем доступ к сообщению исключения внутри блока `except`:

```python
try:
    raise ValueError("A sample value error")
except ValueError as e:
    print("Exception:", str(e))
```

> Примечание: Всегда рассматривайте возможность использования встроенных классов исключений, прежде чем создавать собственные, так как ваши потребности уже могут быть удовлетворены стандартной библиотекой Python.

## Использование Исключений при Проектировании Приложения

При работе с Python, аккуратное обращение с ошибками является критически важной частью проектирования надежных приложений. Конструкция `try except` позволяет вам перехватывать и обрабатывать ошибки, предотвращая непредвиденное аварийное завершение работы программы. Обработка исключений не только о перехвате ошибок, но и о предоставлении значимых сообщений об ошибках и, при необходимости, об облегчении процесса разработки или отладки путем вывода трассировки стека. Давайте рассмотрим, как можно эффективно проектировать исключения в Python.

### Использование Сообщений об Ошибках `try/except`

Когда происходит ошибка, крайне важно предоставить пользователю или разработчику ясное и информативное сообщение об ошибке. Это можно достигнуть с помощью блоков `try` и `except` в Python. Вот пример:

```python
try:
    # Code block where you suspect an error might occur
    result = 10 / 0
except ZeroDivisionError as e:
    print(f"An error occurred: {e}")
```

В этом примере, если происходит деление на ноль, блок `except` перехватывает `ZeroDivisionError` и выводит пользовательское сообщение об ошибке.

### Пример: Печать Стека Исключений

Для целей отладки может быть важно увидеть последовательность вызовов функций, которые привели к ошибке. Вот где печать стека вызовов становится полезной. Python предоставляет модуль [traceback](https://docs.python.org/3/library/traceback.html), который может быть использован для `print` стека вызовов. Вот как это можно сделать:

```python
import traceback

try:
    # Code block where an error is expected
    result = 10 / 0
except ZeroDivisionError:
    traceback.print_exc()
```

Этот фрагмент кода не только перехватит `ZeroDivisionError`, но и `print` стек вызовов, что упростит отладку ошибки.

### Лучшие Практики Проектирования Исключений

При обработке исключений следует придерживаться нескольких лучших практик:

1. **Перехватывайте конкретные исключения**: Всегда пытайтесь перехватывать конкретные исключения, а не перехватывать все исключения обобщенно. Это предотвращает незамеченное игнорирование непреднамеренных ошибок.

2. **Предоставляйте информативные сообщения**: При перехвате исключений обязательно предоставляйте информативные и понятные пользователю сообщения об ошибках.

3. **Используйте Finally для очистки**: Используйте блок `finally` для того, чтобы убедиться, что действия по очистке выполняются, такие как закрытие файлов или освобождение ресурсов, независимо от того, было ли исключение перехвачено или нет.

> Примечание: Важно найти баланс между перехватом конкретных исключений и избеганием слишком детализированной обработки ошибок, которая может сделать код громоздким и трудным для поддержки.
